Workbook
Name UPDATE: 'Data Sheet'!$E$1

Sheet Profit & Loss
A1: ='Data Sheet'!B1 -> WIPRO LTD | H1: =UPDATE | M1: SCREENER.IN
A3: Narration | B3: ='Data Sheet'!B16 -> 42460 | C3: ='Data Sheet'!C16 -> 42825 | D3: ='Data Sheet'!D16 -> 43190 | E3: ='Data Sheet'!E16 -> 43555 | F3: ='Data Sheet'!F16 -> 43921 | G3: ='Data Sheet'!G16 -> 44286 | H3: ='Data Sheet'!H16 -> 44651 | I3: ='Data Sheet'!I16 -> 45016 | ... K3: ='Data Sheet'!K16 -> 45747 | L3: Trailing | M3: Best Case | N3: Worst Case
A4: Sales | B4: ='Data Sheet'!B17 -> 51244 | C4: ='Data Sheet'!C17 -> 55448.4 | D4: ='Data Sheet'!D17 -> 54487.1 | E4: ='Data Sheet'!E17 -> 59018.9 | F4: ='Data Sheet'!F17 -> 61137.6 | G4: ='Data Sheet'!G17 -> 61934.9 | H4: ='Data Sheet'!H17 -> 79312 | I4: ='Data Sheet'!I17 -> 90487.6 | ... K4: ='Data Sheet'!K17 -> 89088.4 | L4: =SUM(Quarters!H4:K4) -> 89654.9 | M4: =$K4+M23*K4 -> 92608.016 | N4: =$K4+N23*L4 -> 89658.502
A5: Expenses | B5: =SUM('Data Sheet'!B18,'Data Sheet'!B20:B24, -1*'Data Sheet'!B19) -> 40448.2 | C5: =SUM('Data Sheet'!C18,'Data Sheet'!C20:C24, -1*'Data Sheet'!C19) -> 44127.5 | D5: =SUM('Data Sheet'!D18,'Data Sheet'!D20:D24, -1*'Data Sheet'!D19) -> 44100 | E5: =SUM('Data Sheet'!E18,'Data Sheet'!E20:E24, -1*'Data Sheet'!E19) -> 47406.3 | F5: =SUM('Data Sheet'!F18,'Data Sheet'!F20:F24, -1*'Data Sheet'!F19) -> 48795.3 | G5: =SUM('Data Sheet'!G18,'Data Sheet'!G20:G24, -1*'Data Sheet'!G19) -> 47163.5 | H5: =SUM('Data Sheet'!H18,'Data Sheet'!H20:H24, -1*'Data Sheet'!H19) -> 62627.8 | I5: =SUM('Data Sheet'!I18,'Data Sheet'!I20:I24, -1*'Data Sheet'!I19) -> 73648.6 | ... K5: =SUM('Data Sheet'!K18,'Data Sheet'!K20:K24, -1*'Data Sheet'!K19) -> 71067.2 | L5: =SUM(Quarters!H5:K5) -> 71885.6 | M5: =M4-M6 -> 74253.418 | N5: =N4-N6 -> 72477.315
A6: Operating Profit | B6: =B4-B5 -> 10795.8 | C6: =C4-C5 -> 11320.9 | D6: =D4-D5 -> 10387.1 | E6: =E4-E5 -> 11612.6 | F6: =F4-F5 -> 12342.3 | G6: =G4-G5 -> 14771.4 | H6: =H4-H5 -> 16684.2 | I6: =I4-I5 -> 16839 | ... K6: =K4-K5 -> 18021.2 | L6: =SUM(Quarters!H6:K6) -> 17769.3 | M6: =M4*M24 -> 18354.598 | N6: =N4*N24 -> 17181.187
A7: Other Income | B7: ='Data Sheet'!B25 -> 2752.2 | C7: ='Data Sheet'!C25 -> 2622.6 | D7: ='Data Sheet'!D25 -> 2549.8 | E7: ='Data Sheet'!E25 -> 2613.8 | F7: ='Data Sheet'!F25 -> 2727.9 | G7: ='Data Sheet'!G25 -> 2403.7 | H7: ='Data Sheet'!H25 -> 2066.9 | I7: ='Data Sheet'!I25 -> 2274.6 | ... K7: ='Data Sheet'!K25 -> 3909.4 | L7: =SUM(Quarters!H7:K7) -> 4256.4 | M7: 0 | N7: 0
A8: Depreciation | B8: ='Data Sheet'!B26 -> 1496.1 | C8: ='Data Sheet'!C26 -> 2310 | D8: ='Data Sheet'!D26 -> 2111.7 | E8: ='Data Sheet'!E26 -> 1946.7 | F8: ='Data Sheet'!F26 -> 2085.5 | G8: ='Data Sheet'!G26 -> 2763.4 | H8: ='Data Sheet'!H26 -> 3077.8 | I8: ='Data Sheet'!I26 -> 3340.2 | ... K8: ='Data Sheet'!K26 -> 2957.9 | L8: =SUM(Quarters!H8:K8) -> 2775.4 | M8: =+$L8 -> 2775.4 | N8: =+$L8 -> 2775.4
A9: Interest | B9: ='Data Sheet'!B27 -> 558.2 | C9: ='Data Sheet'!C27 -> 594.2 | D9: ='Data Sheet'!D27 -> 583 | E9: ='Data Sheet'!E27 -> 737.5 | F9: ='Data Sheet'!F27 -> 732.8 | G9: ='Data Sheet'!G27 -> 508.8 | H9: ='Data Sheet'!H27 -> 532.5 | I9: ='Data Sheet'!I27 -> 1007.7 | ... K9: ='Data Sheet'!K27 -> 1477 | L9: =SUM(Quarters!H9:K9) -> 1513.3 | M9: =+$L9 -> 1513.3 | N9: =+$L9 -> 1513.3
A10: Profit before tax | B10: ='Data Sheet'!B28 -> 11493.7 | C10: ='Data Sheet'!C28 -> 11039.3 | D10: ='Data Sheet'!D28 -> 10242.2 | E10: ='Data Sheet'!E28 -> 11542.2 | F10: ='Data Sheet'!F28 -> 12251.9 | G10: ='Data Sheet'!G28 -> 13902.9 | H10: ='Data Sheet'!H28 -> 15140.8 | I10: ='Data Sheet'!I28 -> 14765.7 | ... K10: ='Data Sheet'!K28 -> 17495.7 | L10: =SUM(Quarters!H10:K10) -> 17737 | M10: =M6+M7-SUM(M8:M9) -> 14065.898 | N10: =N6+N7-SUM(N8:N9) -> 12892.487
A11: Tax | B11: ='Data Sheet'!B29 -> 2536.6 | C11: ='Data Sheet'!C29 -> 2521.4 | D11: ='Data Sheet'!D29 -> 2239.1 | E11: ='Data Sheet'!E29 -> 2524.3 | F11: ='Data Sheet'!F29 -> 2480.1 | G11: ='Data Sheet'!G29 -> 3034.9 | H11: ='Data Sheet'!H29 -> 2897.4 | I11: ='Data Sheet'!I29 -> 3399.2 | ... K11: ='Data Sheet'!K29 -> 4277.7 | L11: =SUM(Quarters!H11:K11) -> 4183.3 | M11: =IF($L10>0,$L11/$L10,0) -> 0.23585161 | N11: =IF($L10>0,$L11/$L10,0) -> 0.23585161
A12: Net profit | B12: ='Data Sheet'!B30 -> 8907.9 | C12: ='Data Sheet'!C30 -> 8493.1 | D12: ='Data Sheet'!D30 -> 8002.8 | E12: ='Data Sheet'!E30 -> 9003.7 | F12: ='Data Sheet'!F30 -> 9722.3 | G12: ='Data Sheet'!G30 -> 10796.4 | H12: ='Data Sheet'!H30 -> 12229.6 | I12: ='Data Sheet'!I30 -> 11350 | ... K12: ='Data Sheet'!K30 -> 13135.4 | L12: =SUM(Quarters!H12:K12) -> 13500 | M12: =M10-M11*M10 -> 10748.433 | N12: =N10-N11*N10 -> 9851.7733
A13: EPS | B13: =IF('Data Sheet'!B93>0,B12/'Data Sheet'!B93,0) -> 6.7601882 | C13: =IF('Data Sheet'!C93>0,C12/'Data Sheet'!C93,0) -> 6.5508916 | D13: =IF('Data Sheet'!D93>0,D12/'Data Sheet'!D93,0) -> 6.6338956 | E13: =IF('Data Sheet'!E93>0,E12/'Data Sheet'!E93,0) -> 7.4608673 | F13: =IF('Data Sheet'!F93>0,F12/'Data Sheet'!F93,0) -> 8.5084058 | G13: =IF('Data Sheet'!G93>0,G12/'Data Sheet'!G93,0) -> 9.8522581 | H13: =IF('Data Sheet'!H93>0,H12/'Data Sheet'!H93,0) -> 11.154222 | I13: =IF('Data Sheet'!I93>0,I12/'Data Sheet'!I93,0) -> 10.340932 | ... K13: =IF('Data Sheet'!K93>0,K12/'Data Sheet'!K93,0) -> 12.543234 | L13: =IF('Data Sheet'!$B6>0,'Profit & Loss'!L12/'Data Sheet'!$B6,0) -> 12.873218 | M13: =IF('Data Sheet'!$B6>0,'Profit & Loss'!M12/'Data Sheet'!$B6,0) -> 10.249401 | N13: =IF('Data Sheet'!$B6>0,'Profit & Loss'!N12/'Data Sheet'!$B6,0) -> 9.3943721
A14: Price to earning | B14: =IF(B15>0,B15/B13,"") -> 15.650452 | C14: =IF(C15>0,C15/C13,"") -> 14.761349 | D14: =IF(D15>0,D15/D13,"") -> 15.89413 | E14: =IF(E15>0,E15/E13,"") -> 17.075763 | F14: =IF(F15>0,F15/F13,"") -> 11.559157 | G14: =IF(G15>0,G15/G13,"") -> 21.018532 | H14: =IF(H15>0,H15/H13,"") -> 26.532555 | I14: =IF(I15>0,I15/I13,"") -> 17.660884 | ... K14: =IF(K15>0,K15/K13,"") -> 20.907686 | L14: =IF(L13>0,L15/L13,0) -> 20.798996 | M14: =M25 -> 20.798996 | N14: =N25 -> 18.597417
A15: Price | B15: ='Data Sheet'!B90 -> 105.8 | C15: ='Data Sheet'!C90 -> 96.7 | D15: ='Data Sheet'!D90 -> 105.44 | E15: ='Data Sheet'!E90 -> 127.4 | F15: ='Data Sheet'!F90 -> 98.35 | G15: ='Data Sheet'!G90 -> 207.08 | H15: ='Data Sheet'!H90 -> 295.95 | I15: ='Data Sheet'!I90 -> 182.63 | ... K15: ='Data Sheet'!K90 -> 262.25 | L15: ='Data Sheet'!B8 -> 267.75 | M15: =M13*M14 -> 213.17725 | N15: =N13*N14 -> 174.71105
A17: RATIOS:
A18: Dividend Payout | B18: =IF('Data Sheet'!B30>0, 'Data Sheet'!B31/'Data Sheet'!B30, 0) -> 0.16640286 | C18: =IF('Data Sheet'!C30>0, 'Data Sheet'!C31/'Data Sheet'!C30, 0) -> 0.057234696 | D18: =IF('Data Sheet'!D30>0, 'Data Sheet'!D31/'Data Sheet'!D30, 0) -> 0.056530214 | E18: =IF('Data Sheet'!E30>0, 'Data Sheet'!E31/'Data Sheet'!E30, 0) -> 0.067016893 | F18: =IF('Data Sheet'!F30>0, 'Data Sheet'!F31/'Data Sheet'!F30, 0) -> 0.058766958 | G18: =IF('Data Sheet'!G30>0, 'Data Sheet'!G31/'Data Sheet'!G30, 0) -> 0.050748398 | H18: =IF('Data Sheet'!H30>0, 'Data Sheet'!H31/'Data Sheet'!H30, 0) -> 0.26895401 | I18: =IF('Data Sheet'!I30>0, 'Data Sheet'!I31/'Data Sheet'!I30, 0) -> 0.048352423 | ... K18: =IF('Data Sheet'!K30>0, 'Data Sheet'!K31/'Data Sheet'!K30, 0) -> 0.47834097
A19: OPM | B19: =IF(B6>0,B6/B4,0) -> 0.21067442 | C19: =IF(C6>0,C6/C4,0) -> 0.20417 | D19: =IF(D6>0,D6/D4,0) -> 0.19063411 | E19: =IF(E6>0,E6/E4,0) -> 0.1967607 | F19: =IF(F6>0,F6/F4,0) -> 0.2018774 | G19: =IF(G6>0,G6/G4,0) -> 0.23849881 | H19: =IF(H6>0,H6/H4,0) -> 0.21036161 | I19: =IF(I6>0,I6/I4,0) -> 0.1860918 | ... L19: =IF(L6>0,L6/L4,0) -> 0.19819664
G22: TRENDS: | H22: 10 YEARS | I22: 7 YEARS | J22: 5 YEARS | K22: 3 YEARS | L22: RECENT | M22: BEST | N22: WORST
G23: Sales Growth | H23: =IF(B4=0,"",POWER($K4/B4,1/9)-1) -> 0.063375034 | I23: =IF(D4=0,"",POWER($K4/D4,1/7)-1) -> 0.07276334 | J23: =IF(F4=0,"",POWER($K4/F4,1/5)-1) -> 0.078208012 | K23: =IF(H4=0,"",POWER($K4/H4, 1/3)-1) -> 0.039507002 | L23: =IF(ISERROR(MAX(IF(J4=0,"",(K4-J4)/J4),IF(K4=0,"",(L4-K4)/K4))),"",MAX(IF(J4=0,"",(K4-J4)/J4),IF(K4=0,"",(L4-K4)/K4))) -> 0.0063588526 | M23: =MAX(K23:L23) -> 0.039507002 | N23: =MIN(H23:L23) -> 0.0063588526
G24: OPM | H24: =IF(SUM(B4:$K$4)=0,"",SUMPRODUCT(B19:$K$19,B4:$K$4)/SUM(B4:$K$4)) -> 0.20165216 | I24: =IF(SUM(E4:$K$4)=0,"",SUMPRODUCT(E19:$K$19,E4:$K$4)/SUM(E4:$K$4)) -> 0.20164913 | J24: =IF(SUM(G4:$K$4)=0,"",SUMPRODUCT(G19:$K$19,G4:$K$4)/SUM(G4:$K$4)) -> 0.20231782 | K24: =IF(SUM(I4:$K$4)=0, "", SUMPRODUCT(I19:$K$19,I4:$K$4)/SUM(I4:$K$4)) -> 0.1916292 | L24: =L19 -> 0.19819664 | M24: =MAX(K24:L24) -> 0.19819664 | N24: =MIN(H24:L24) -> 0.1916292
G25: Price to Earning | H25: =IF(ISERROR(AVERAGEIF(B14:$L14,">0")),"",AVERAGEIF(B14:$L14,">0")) -> 18.597417 | I25: =IF(ISERROR(AVERAGEIF(E14:$L14,">0")),"",AVERAGEIF(E14:$L14,">0")) -> 19.783206 | J25: =IF(ISERROR(AVERAGEIF(G14:$L14,">0")),"",AVERAGEIF(G14:$L14,">0")) -> 21.605122 | K25: =IF(ISERROR(AVERAGEIF(I14:$L14,">0")),"",AVERAGEIF(I14:$L14,">0")) -> 20.519911 | L25: =L14 -> 20.798996 | M25: =MAX(K25:L25) -> 20.798996 | N25: =MIN(H25:L25) -> 18.597417

Sheet Quarters
A1: ='Profit & Loss'!A1 -> WIPRO LTD | E1: =UPDATE | J1: SCREENER.IN
A3: Narration | B3: ='Data Sheet'!B41 -> 45107 | C3: ='Data Sheet'!C41 -> 45199 | D3: ='Data Sheet'!D41 -> 45291 | E3: ='Data Sheet'!E41 -> 45382 | F3: ='Data Sheet'!F41 -> 45473 | G3: ='Data Sheet'!G41 -> 45565 | H3: ='Data Sheet'!H41 -> 45657 | I3: ='Data Sheet'!I41 -> 45747 | ... K3: ='Data Sheet'!K41 -> 45930
A4: Sales | B4: ='Data Sheet'!B42 -> 22831 | C4: ='Data Sheet'!C42 -> 22515.9 | D4: ='Data Sheet'!D42 -> 22205.1 | E4: ='Data Sheet'!E42 -> 22208.3 | F4: ='Data Sheet'!F42 -> 21963.8 | G4: ='Data Sheet'!G42 -> 22301.6 | H4: ='Data Sheet'!H42 -> 22318.8 | I4: ='Data Sheet'!I42 -> 22504.2 | ... K4: ='Data Sheet'!K42 -> 22697.3
A5: Expenses | B5: ='Data Sheet'!B43 -> 18627.4 | C5: ='Data Sheet'!C43 -> 18546.2 | D5: ='Data Sheet'!D43 -> 18006.8 | E5: ='Data Sheet'!E43 -> 17827.7 | F5: ='Data Sheet'!F43 -> 17614.2 | G5: ='Data Sheet'!G43 -> 17798.3 | H5: ='Data Sheet'!H43 -> 17779 | I5: ='Data Sheet'!I43 -> 17880.2 | ... K5: ='Data Sheet'!K43 -> 18324.9
A6: Operating Profit | B6: ='Data Sheet'!B50 -> 4203.6 | C6: ='Data Sheet'!C50 -> 3969.7 | D6: ='Data Sheet'!D50 -> 4198.3 | E6: ='Data Sheet'!E50 -> 4380.6 | F6: ='Data Sheet'!F50 -> 4349.6 | G6: ='Data Sheet'!G50 -> 4503.3 | H6: ='Data Sheet'!H50 -> 4539.8 | I6: ='Data Sheet'!I50 -> 4624 | ... K6: ='Data Sheet'!K50 -> 4372.4
A7: Other Income | B7: ='Data Sheet'!B44 -> 640.5 | C7: ='Data Sheet'!C44 -> 739.8 | D7: ='Data Sheet'!D44 -> 597.9 | E7: ='Data Sheet'!E44 -> 652.9 | F7: ='Data Sheet'!F44 -> 729.7 | G7: ='Data Sheet'!G44 -> 962.2 | H7: ='Data Sheet'!H44 -> 1004.6 | I7: ='Data Sheet'!I44 -> 1217.4 | ... K7: ='Data Sheet'!K44 -> 962.9
A8: Depreciation | B8: ='Data Sheet'!B45 -> 738 | C8: ='Data Sheet'!C45 -> 897 | D8: ='Data Sheet'!D45 -> 931.6 | E8: ='Data Sheet'!E45 -> 840.5 | F8: ='Data Sheet'!F45 -> 728.9 | G8: ='Data Sheet'!G45 -> 830.8 | H8: ='Data Sheet'!H45 -> 676.5 | I8: ='Data Sheet'!I45 -> 721.7 | ... K8: ='Data Sheet'!K45 -> 691.7
A9: Interest | B9: ='Data Sheet'!B46 -> 308.6 | C9: ='Data Sheet'!C46 -> 303.3 | D9: ='Data Sheet'!D46 -> 312.5 | E9: ='Data Sheet'!E46 -> 330.8 | F9: ='Data Sheet'!F46 -> 328.8 | G9: ='Data Sheet'!G46 -> 356.9 | H9: ='Data Sheet'!H46 -> 414.6 | I9: ='Data Sheet'!I46 -> 376.7 | ... K9: ='Data Sheet'!K46 -> 361.2
A10: Profit before tax | B10: ='Data Sheet'!B47 -> 3797.5 | C10: ='Data Sheet'!C47 -> 3509.2 | D10: ='Data Sheet'!D47 -> 3552.1 | E10: ='Data Sheet'!E47 -> 3862.2 | F10: ='Data Sheet'!F47 -> 4021.6 | G10: ='Data Sheet'!G47 -> 4277.8 | H10: ='Data Sheet'!H47 -> 4453.3 | I10: ='Data Sheet'!I47 -> 4743 | ... K10: ='Data Sheet'!K47 -> 4282.4
A11: Tax | B11: ='Data Sheet'!B48 -> 911.5 | C11: ='Data Sheet'!C48 -> 841.9 | D11: ='Data Sheet'!D48 -> 851.5 | E11: ='Data Sheet'!E48 -> 1004 | F11: ='Data Sheet'!F48 -> 985 | G11: ='Data Sheet'!G48 -> 1051.2 | H11: ='Data Sheet'!H48 -> 1086.6 | I11: ='Data Sheet'!I48 -> 1154.9 | ... K11: ='Data Sheet'!K48 -> 1020
A12: Net profit | B12: ='Data Sheet'!B49 -> 2870.1 | C12: ='Data Sheet'!C49 -> 2646.3 | D12: ='Data Sheet'!D49 -> 2694.2 | E12: ='Data Sheet'!E49 -> 2834.6 | F12: ='Data Sheet'!F49 -> 3003.2 | G12: ='Data Sheet'!G49 -> 3208.8 | H12: ='Data Sheet'!H49 -> 3353.8 | I12: ='Data Sheet'!I49 -> 3569.6 | ... K12: ='Data Sheet'!K49 -> 3246.2
A14: OPM | B14: =IF(B4>0,B6/B4,"") -> 0.18411809 | C14: =IF(C4>0,C6/C4,"") -> 0.17630652 | D14: =IF(D4>0,D6/D4,"") -> 0.18906918 | E14: =IF(E4>0,E6/E4,"") -> 0.19725058 | F14: =IF(F4>0,F6/F4,"") -> 0.19803495 | G14: =IF(G4>0,G6/G4,"") -> 0.20192722 | H14: =IF(H4>0,H6/H4,"") -> 0.20340699 | I14: =IF(I4>0,I6/I4,"") -> 0.20547276 | ... K14: =IF(K4>0,K6/K4,"") -> 0.19263965

Sheet Balance Sheet
A1: ='Profit & Loss'!A1 -> WIPRO LTD | E1: =UPDATE | J1: SCREENER.IN
A3: Narration | B3: ='Data Sheet'!B56 -> 42460 | C3: ='Data Sheet'!C56 -> 42825 | D3: ='Data Sheet'!D56 -> 43190 | E3: ='Data Sheet'!E56 -> 43555 | F3: ='Data Sheet'!F56 -> 43921 | G3: ='Data Sheet'!G56 -> 44286 | H3: ='Data Sheet'!H56 -> 44651 | I3: ='Data Sheet'!I56 -> 45016 | ... K3: ='Data Sheet'!K56 -> 45747
A4: Equity Share Capital | B4: ='Data Sheet'!B57 -> 494.1 | C4: ='Data Sheet'!C57 -> 486.1 | D4: ='Data Sheet'!D57 -> 904.8 | E4: ='Data Sheet'!E57 -> 1206.8 | F4: ='Data Sheet'!F57 -> 1142.7 | G4: ='Data Sheet'!G57 -> 1095.8 | H4: ='Data Sheet'!H57 -> 1096.4 | I4: ='Data Sheet'!I57 -> 1097.6 | ... K4: ='Data Sheet'!K57 -> 2094.4
A5: Reserves | B5: ='Data Sheet'!B58 -> 45650.7 | C5: ='Data Sheet'!C58 -> 51184.1 | D5: ='Data Sheet'!D58 -> 47021.5 | E5: ='Data Sheet'!E58 -> 55215.8 | F5: ='Data Sheet'!F58 -> 54179 | G5: ='Data Sheet'!G58 -> 53805.2 | H5: ='Data Sheet'!H58 -> 64306.6 | I5: ='Data Sheet'!I58 -> 76570.3 | ... K5: ='Data Sheet'!K58 -> 80736.5
A6: Borrowings | B6: ='Data Sheet'!B59 -> 12522.1 | C6: ='Data Sheet'!C59 -> 14241.2 | D6: ='Data Sheet'!D59 -> 13901.2 | E6: ='Data Sheet'!E59 -> 9946.7 | F6: ='Data Sheet'!F59 -> 9724 | G6: ='Data Sheet'!G59 -> 10451.4 | H6: ='Data Sheet'!H59 -> 17592.9 | I6: ='Data Sheet'!I59 -> 17466.6 | ... K6: ='Data Sheet'!K59 -> 19203.5
A7: Other Liabilities | B7: ='Data Sheet'!B60 -> 12923.5 | C7: ='Data Sheet'!C60 -> 12760.8 | D7: ='Data Sheet'!D60 -> 13563.3 | E7: ='Data Sheet'!E60 -> 16217.1 | F7: ='Data Sheet'!F60 -> 15953.9 | G7: ='Data Sheet'!G60 -> 17213.4 | H7: ='Data Sheet'!H60 -> 24279.7 | I7: ='Data Sheet'!I60 -> 21789.2 | ... K7: ='Data Sheet'!K60 -> 26361.5
A8: Total | B8: ='Data Sheet'!B61 -> 71590.4 | C8: ='Data Sheet'!C61 -> 78672.2 | D8: ='Data Sheet'!D61 -> 75390.8 | E8: ='Data Sheet'!E61 -> 82586.4 | F8: ='Data Sheet'!F61 -> 80999.6 | G8: ='Data Sheet'!G61 -> 82565.8 | H8: ='Data Sheet'!H61 -> 107275.6 | I8: ='Data Sheet'!I61 -> 116923.7 | ... K8: ='Data Sheet'!K61 -> 128395.9
F9: =F4+F5 -> 55321.7 | G9: =G4+G5 -> 54901 | H9: =H4+H5 -> 65403 | I9: =I4+I5 -> 77667.9 | J9: =J4+J5 -> 74988.3 | K9: =K4+K5 -> 82830.9
A10: Net Block | B10: ='Data Sheet'!B62 -> 17279.1 | C10: ='Data Sheet'!C62 -> 19886.5 | D10: ='Data Sheet'!D62 -> 18126.7 | E10: ='Data Sheet'!E62 -> 17464.7 | F10: ='Data Sheet'!F62 -> 22062.1 | G10: ='Data Sheet'!G62 -> 23040.3 | H10: ='Data Sheet'!H62 -> 37989.6 | I10: ='Data Sheet'!I62 -> 44756.8 | ... K10: ='Data Sheet'!K62 -> 45653.5
A11: Capital Work in Progress | B11: ='Data Sheet'!B63 -> 380.6 | C11: ='Data Sheet'!C63 -> 737.7 | D11: ='Data Sheet'!D63 -> 1377.7 | E11: ='Data Sheet'!E63 -> 2141.8 | F11: ='Data Sheet'!F63 -> 1881.1 | G11: ='Data Sheet'!G63 -> 1853.2 | H11: ='Data Sheet'!H63 -> 1601.5 | I11: ='Data Sheet'!I63 -> 617.1 | ... K11: ='Data Sheet'!K63 -> 221.1
A12: Investments | B12: ='Data Sheet'!B64 -> 20915.1 | C12: ='Data Sheet'!C64 -> 29913.3 | D12: ='Data Sheet'!D64 -> 25796.8 | E12: ='Data Sheet'!E64 -> 22886.7 | F12: ='Data Sheet'!F64 -> 20032 | G12: ='Data Sheet'!G64 -> 18774.7 | H12: ='Data Sheet'!H64 -> 26153.8 | I12: ='Data Sheet'!I64 -> 33073.2 | ... K12: ='Data Sheet'!K64 -> 43925.9
A13: Other Assets | B13: ='Data Sheet'!B65 -> 33015.6 | C13: ='Data Sheet'!C65 -> 28134.7 | D13: ='Data Sheet'!D65 -> 30089.6 | E13: ='Data Sheet'!E65 -> 40093.2 | F13: ='Data Sheet'!F65 -> 37024.4 | G13: ='Data Sheet'!G65 -> 38897.6 | H13: ='Data Sheet'!H65 -> 41530.7 | I13: ='Data Sheet'!I65 -> 38476.6 | ... K13: ='Data Sheet'!K65 -> 38595.4
A14: Total | B14: ='Data Sheet'!B66 -> 71590.4 | C14: ='Data Sheet'!C66 -> 78672.2 | D14: ='Data Sheet'!D66 -> 75390.8 | E14: ='Data Sheet'!E66 -> 82586.4 | F14: ='Data Sheet'!F66 -> 80999.6 | G14: ='Data Sheet'!G66 -> 82565.8 | H14: ='Data Sheet'!H66 -> 107275.6 | I14: ='Data Sheet'!I66 -> 116923.7 | ... K14: ='Data Sheet'!K66 -> 128395.9
A16: Working Capital | B16: =B13-B7 -> 20092.1 | C16: =C13-C7 -> 15373.9 | D16: =D13-D7 -> 16526.3 | E16: =E13-E7 -> 23876.1 | F16: =F13-F7 -> 21070.5 | G16: =G13-G7 -> 21684.2 | H16: =H13-H7 -> 17251 | I16: =I13-I7 -> 16687.4 | ... K16: =K13-K7 -> 12233.9
A17: Debtors | B17: ='Data Sheet'!B67 -> 9961.4 | C17: ='Data Sheet'!C67 -> 9484.6 | D17: ='Data Sheet'!D67 -> 10099 | E17: ='Data Sheet'!E67 -> 10048.9 | F17: ='Data Sheet'!F67 -> 10447.4 | G17: ='Data Sheet'!G67 -> 9429.8 | H17: ='Data Sheet'!H67 -> 11521.9 | I17: ='Data Sheet'!I67 -> 12635 | ... K17: ='Data Sheet'!K67 -> 11774.5
A18: Inventory | B18: ='Data Sheet'!B68 -> 539 | C18: ='Data Sheet'!C68 -> 391.5 | D18: ='Data Sheet'!D68 -> 337 | E18: ='Data Sheet'!E68 -> 395.1 | F18: ='Data Sheet'!F68 -> 186.5 | G18: ='Data Sheet'!G68 -> 106.4 | H18: ='Data Sheet'!H68 -> 133.4 | I18: ='Data Sheet'!I68 -> 118.8 | ... K18: ='Data Sheet'!K68 -> 69.4
A20: Debtor Days | B20: =IF('Profit & Loss'!B4>0,'Balance Sheet'!B17/('Profit & Loss'!B4/365),0) -> 70.952912 | C20: =IF('Profit & Loss'!C4>0,'Balance Sheet'!C17/('Profit & Loss'!C4/365),0) -> 62.434245 | D20: =IF('Profit & Loss'!D4>0,'Balance Sheet'!D17/('Profit & Loss'!D4/365),0) -> 67.651518 | E20: =IF('Profit & Loss'!E4>0,'Balance Sheet'!E17/('Profit & Loss'!E4/365),0) -> 62.147016 | F20: =IF('Profit & Loss'!F4>0,'Balance Sheet'!F17/('Profit & Loss'!F4/365),0) -> 62.372435 | G20: =IF('Profit & Loss'!G4>0,'Balance Sheet'!G17/('Profit & Loss'!G4/365),0) -> 55.572496 | H20: =IF('Profit & Loss'!H4>0,'Balance Sheet'!H17/('Profit & Loss'!H4/365),0) -> 53.024681 | I20: =IF('Profit & Loss'!I4>0,'Balance Sheet'!I17/('Profit & Loss'!I4/365),0) -> 50.965823 | ... K20: =IF('Profit & Loss'!K4>0,'Balance Sheet'!K17/('Profit & Loss'!K4/365),0) -> 48.240764
A21: Inventory Turnover | B21: =IF('Balance Sheet'!B18>0,'Profit & Loss'!B4/'Balance Sheet'!B18,0) -> 95.072356 | C21: =IF('Balance Sheet'!C18>0,'Profit & Loss'!C4/'Balance Sheet'!C18,0) -> 141.63065 | D21: =IF('Balance Sheet'!D18>0,'Profit & Loss'!D4/'Balance Sheet'!D18,0) -> 161.68279 | E21: =IF('Balance Sheet'!E18>0,'Profit & Loss'!E4/'Balance Sheet'!E18,0) -> 149.37712 | F21: =IF('Balance Sheet'!F18>0,'Profit & Loss'!F4/'Balance Sheet'!F18,0) -> 327.81555 | G21: =IF('Balance Sheet'!G18>0,'Profit & Loss'!G4/'Balance Sheet'!G18,0) -> 582.09492 | H21: =IF('Balance Sheet'!H18>0,'Profit & Loss'!H4/'Balance Sheet'!H18,0) -> 594.54273 | I21: =IF('Balance Sheet'!I18>0,'Profit & Loss'!I4/'Balance Sheet'!I18,0) -> 761.68013 | ... K21: =IF('Balance Sheet'!K18>0,'Profit & Loss'!K4/'Balance Sheet'!K18,0) -> 1283.6945
A23: Return on Equity | B23: =IF(SUM('Balance Sheet'!B4:B5)>0,'Profit & Loss'!B12/SUM('Balance Sheet'!B4:B5),"") -> 0.19304234 | C23: =IF(SUM('Balance Sheet'!C4:C5)>0,'Profit & Loss'!C12/SUM('Balance Sheet'!C4:C5),"") -> 0.16437134 | D23: =IF(SUM('Balance Sheet'!D4:D5)>0,'Profit & Loss'!D12/SUM('Balance Sheet'!D4:D5),"") -> 0.16698139 | E23: =IF(SUM('Balance Sheet'!E4:E5)>0,'Profit & Loss'!E12/SUM('Balance Sheet'!E4:E5),"") -> 0.15957613 | F23: =IF(SUM('Balance Sheet'!F4:F5)>0,'Profit & Loss'!F12/SUM('Balance Sheet'!F4:F5),"") -> 0.17574116 | G23: =IF(SUM('Balance Sheet'!G4:G5)>0,'Profit & Loss'!G12/SUM('Balance Sheet'!G4:G5),"") -> 0.19665216 | H23: =IF(SUM('Balance Sheet'!H4:H5)>0,'Profit & Loss'!H12/SUM('Balance Sheet'!H4:H5),"") -> 0.18698836 | I23: =IF(SUM('Balance Sheet'!I4:I5)>0,'Profit & Loss'!I12/SUM('Balance Sheet'!I4:I5),"") -> 0.14613502 | ... K23: =IF(SUM('Balance Sheet'!K4:K5)>0,'Profit & Loss'!K12/SUM('Balance Sheet'!K4:K5),"") -> 0.15858092
A24: Return on Capital Emp | C24: =IF((B4+B5+B6+C4+C5+C6)>0,('Profit & Loss'!C10+'Profit & Loss'!C9)*2/(B4+B5+B6+C4+C5+C6),"") -> 0.18676607 | D24: =IF((C4+C5+C6+D4+D5+D6)>0,('Profit & Loss'!D10+'Profit & Loss'!D9)*2/(C4+C5+C6+D4+D5+D6),"") -> 0.16948948 | E24: =IF((D4+D5+D6+E4+E5+E6)>0,('Profit & Loss'!E10+'Profit & Loss'!E9)*2/(D4+D5+D6+E4+E5+E6),"") -> 0.19157576 | F24: =IF((E4+E5+E6+F4+F5+F6)>0,('Profit & Loss'!F10+'Profit & Loss'!F9)*2/(E4+E5+E6+F4+F5+F6),"") -> 0.19761367 | G24: =IF((F4+F5+F6+G4+G5+G6)>0,('Profit & Loss'!G10+'Profit & Loss'!G9)*2/(F4+F5+F6+G4+G5+G6),"") -> 0.22104156 | H24: =IF((G4+G5+G6+H4+H5+H6)>0,('Profit & Loss'!H10+'Profit & Loss'!H9)*2/(G4+G5+G6+H4+H5+H6),"") -> 0.21130407 | I24: =IF((H4+H5+H6+I4+I5+I6)>0,('Profit & Loss'!I10+'Profit & Loss'!I9)*2/(H4+H5+H6+I4+I5+I6),"") -> 0.17709947 | J24: =IF((I4+I5+I6+J4+J5+J6)>0,('Profit & Loss'!J10+'Profit & Loss'!J9)*2/(I4+I5+I6+J4+J5+J6),"") -> 0.17124601 | K24: =IF((J4+J5+J6+K4+K5+K6)>0,('Profit & Loss'!K10+'Profit & Loss'!K9)*2/(J4+J5+J6+K4+K5+K6),"") -> 0.19611283

Sheet Cash Flow
A1: ='Balance Sheet'!A1 -> WIPRO LTD | E1: =UPDATE | J1: SCREENER.IN
A3: Narration | B3: ='Data Sheet'!B81 -> 42460 | C3: ='Data Sheet'!C81 -> 42825 | D3: ='Data Sheet'!D81 -> 43190 | E3: ='Data Sheet'!E81 -> 43555 | F3: ='Data Sheet'!F81 -> 43921 | G3: ='Data Sheet'!G81 -> 44286 | H3: ='Data Sheet'!H81 -> 44651 | I3: ='Data Sheet'!I81 -> 45016 | ... K3: ='Data Sheet'!K81 -> 45747
A4: Cash from Operating Activity | B4: ='Data Sheet'!B82 -> 7887.3 | C4: ='Data Sheet'!C82 -> 9277.3 | D4: ='Data Sheet'!D82 -> 8423.3 | E4: ='Data Sheet'!E82 -> 11631.6 | F4: ='Data Sheet'!F82 -> 10064.3 | G4: ='Data Sheet'!G82 -> 14755 | H4: ='Data Sheet'!H82 -> 11079.7 | I4: ='Data Sheet'!I82 -> 13060.1 | ... K4: ='Data Sheet'!K82 -> 16942.6
A5: Cash from Investing Activity | B5: ='Data Sheet'!B83 -> -13760.7 | C5: ='Data Sheet'!C83 -> -11769.5 | D5: ='Data Sheet'!D83 -> 3595.3 | E5: ='Data Sheet'!E83 -> 5065.2 | F5: ='Data Sheet'!F83 -> 3593.4 | G5: ='Data Sheet'!G83 -> 684.9 | H5: ='Data Sheet'!H83 -> -22321.3 | I5: ='Data Sheet'!I83 -> -8169.2 | ... K5: ='Data Sheet'!K83 -> -8044
A6: Cash from Financing Activity | B6: ='Data Sheet'!B84 -> -158.7 | C6: ='Data Sheet'!C84 -> -2275.2 | D6: ='Data Sheet'!D84 -> -12997.8 | E6: ='Data Sheet'!E84 -> -4936.9 | F6: ='Data Sheet'!F84 -> -15099.8 | G6: ='Data Sheet'!G84 -> -12884 | H6: ='Data Sheet'!H84 -> 4658.6 | I6: ='Data Sheet'!I84 -> -6088.1 | ... K6: ='Data Sheet'!K84 -> -6396.3
A7: Net Cash Flow | B7: ='Data Sheet'!B85 -> -6032.1 | C7: ='Data Sheet'!C85 -> -4767.4 | D7: ='Data Sheet'!D85 -> -979.2 | E7: ='Data Sheet'!E85 -> 11759.9 | F7: ='Data Sheet'!F85 -> -1442.1 | G7: ='Data Sheet'!G85 -> 2555.9 | H7: ='Data Sheet'!H85 -> -6583 | I7: ='Data Sheet'!I85 -> -1197.2 | ... K7: ='Data Sheet'!K85 -> 2502.3

Sheet Data Sheet
A1: COMPANY NAME | B1: WIPRO LTD | E1: =IF(B2<>B3, "A NEW VERSION OF THE WORKSHEET IS AVAILABLE", "")
A2: LATEST VERSION | B2: 2.1 | E2: PLEASE DO NOT MAKE ANY CHANGES TO THIS SHEET
A3: CURRENT VERSION | B3: 2.1
A5: META
A6: Number of shares | B6: =IF(B9>0, B9/B8, 0) -> 1048.6889
A7: Face Value | B7: 2
A8: Current Price | B8: 267.75
A9: Market Capitalization | B9: 280786.44
A15: PROFIT & LOSS
A16: Report Date | B16: 42460 | C16: 42825 | D16: 43190 | E16: 43555 | F16: 43921 | G16: 44286 | H16: 44651 | I16: 45016 | J16: 45382 | K16: 45747
A17: Sales | B17: 51244 | C17: 55448.4 | D17: 54487.1 | E17: 59018.9 | F17: 61137.6 | G17: 61934.9 | H17: 79312 | I17: 90487.6 | J17: 89760.3 | K17: 89088.4
A18: Raw Material Cost | B18: 3055.4 | C18: 2556 | D18: 1843.4 | E18: 1407.3 | F18: 936 | G18: 695.7 | H18: 673.5 | I18: 649.4
A19: Change in Inventory | B19: 60.5 | C19: -141.1 | D19: -50.5 | E19: 67.3 | F19: -202.2 | G19: -31.5 | H19: 36.9 | I19: -15
A20: Power and Fuel
A21: Other Mfr. Exp | H21: 12186.8 | I21: 13396.4 | J21: 75702.1 | K21: 74045.8
A22: Employee Cost | B22: 24553.4 | C22: 26808.1 | D22: 27222.3 | E22: 29977.4 | F22: 32657.1 | G22: 33237.1 | H22: 45007.5 | I22: 53764.4 | J22: 54930.1 | K22: 53347.7
A23: Selling and admin | B23: 10517.7 | C23: 13775.7 | D23: 13853.3 | E23: 14796.3 | F23: 14350.4 | G23: 12523.8 | H23: 4665.4 | I23: 5599.2 | J23: -57785.4 | K23: -56313.3
A24: Other Expenses | B24: 2382.2 | C24: 846.6 | D24: 1130.5 | E24: 1292.6 | F24: 649.6 | G24: 675.4 | H24: 131.5 | I24: 224.2 | J24: 161 | K24: -13
A25: Other Income | B25: 2752.2 | C25: 2622.6 | D25: 2549.8 | E25: 2613.8 | F25: 2727.9 | G25: 2403.7 | H25: 2066.9 | I25: 2274.6 | J25: 2630.8 | K25: 3909.4
A26: Depreciation | B26: 1496.1 | C26: 2310 | D26: 2111.7 | E26: 1946.7 | F26: 2085.5 | G26: 2763.4 | H26: 3077.8 | I26: 3340.2 | J26: 3407.1 | K26: 2957.9
A27: Interest | B27: 558.2 | C27: 594.2 | D27: 583 | E27: 737.5 | F27: 732.8 | G27: 508.8 | H27: 532.5 | I27: 1007.7 | J27: 1255.2 | K27: 1477
A28: Profit before tax | B28: 11493.7 | C28: 11039.3 | D28: 10242.2 | E28: 11542.2 | F28: 12251.9 | G28: 13902.9 | H28: 15140.8 | I28: 14765.7 | J28: 14721 | K28: 17495.7
A29: Tax | B29: 2536.6 | C29: 2521.4 | D29: 2239.1 | E29: 2524.3 | F29: 2480.1 | G29: 3034.9 | H29: 2897.4 | I29: 3399.2 | J29: 3608.9 | K29: 4277.7
A30: Net profit | B30: 8907.9 | C30: 8493.1 | D30: 8002.8 | E30: 9003.7 | F30: 9722.3 | G30: 10796.4 | H30: 12229.6 | I30: 11350 | J30: 11045.2 | K30: 13135.4
A31: Dividend Amount | B31: 1482.3 | C31: 486.1 | D31: 452.4 | E31: 603.4 | F31: 571.35 | G31: 547.9 | H31: 3289.2 | I31: 548.8 | J31: 522.5 | K31: 6283.2
A40: Quarters
A41: Report Date | B41: 45107 | C41: 45199 | D41: 45291 | E41: 45382 | F41: 45473 | G41: 45565 | H41: 45657 | I41: 45747 | J41: 45838 | K41: 45930
A42: Sales | B42: 22831 | C42: 22515.9 | D42: 22205.1 | E42: 22208.3 | F42: 21963.8 | G42: 22301.6 | H42: 22318.8 | I42: 22504.2 | J42: 22134.6 | K42: 22697.3
A43: Expenses | B43: 18627.4 | C43: 18546.2 | D43: 18006.8 | E43: 17827.7 | F43: 17614.2 | G43: 17798.3 | H43: 17779 | I43: 17880.2 | J43: 17901.5 | K43: 18324.9
A44: Other Income | B44: 640.5 | C44: 739.8 | D44: 597.9 | E44: 652.9 | F44: 729.7 | G44: 962.2 | H44: 1004.6 | I44: 1217.4 | J44: 1071.5 | K44: 962.9
A45: Depreciation | B45: 738 | C45: 897 | D45: 931.6 | E45: 840.5 | F45: 728.9 | G45: 830.8 | H45: 676.5 | I45: 721.7 | J45: 685.5 | K45: 691.7
A46: Interest | B46: 308.6 | C46: 303.3 | D46: 312.5 | E46: 330.8 | F46: 328.8 | G46: 356.9 | H46: 414.6 | I46: 376.7 | J46: 360.8 | K46: 361.2
A47: Profit before tax | B47: 3797.5 | C47: 3509.2 | D47: 3552.1 | E47: 3862.2 | F47: 4021.6 | G47: 4277.8 | H47: 4453.3 | I47: 4743 | J47: 4258.3 | K47: 4282.4
A48: Tax | B48: 911.5 | C48: 841.9 | D48: 851.5 | E48: 1004 | F48: 985 | G48: 1051.2 | H48: 1086.6 | I48: 1154.9 | J48: 921.8 | K48: 1020
A49: Net profit | B49: 2870.1 | C49: 2646.3 | D49: 2694.2 | E49: 2834.6 | F49: 3003.2 | G49: 3208.8 | H49: 3353.8 | I49: 3569.6 | J49: 3330.4 | K49: 3246.2
A50: Operating Profit | B50: 4203.6 | C50: 3969.7 | D50: 4198.3 | E50: 4380.6 | F50: 4349.6 | G50: 4503.3 | H50: 4539.8 | I50: 4624 | J50: 4233.1 | K50: 4372.4
A55: BALANCE SHEET
A56: Report Date | B56: 42460 | C56: 42825 | D56: 43190 | E56: 43555 | F56: 43921 | G56: 44286 | H56: 44651 | I56: 45016 | J56: 45382 | K56: 45747
A57: Equity Share Capital | B57: 494.1 | C57: 486.1 | D57: 904.8 | E57: 1206.8 | F57: 1142.7 | G57: 1095.8 | H57: 1096.4 | I57: 1097.6 | J57: 1045 | K57: 2094.4
A58: Reserves | B58: 45650.7 | C58: 51184.1 | D58: 47021.5 | E58: 55215.8 | F58: 54179 | G58: 53805.2 | H58: 64306.6 | I58: 76570.3 | J58: 73943.3 | K58: 80736.5
...

Sheet 5 years financial data
A1: Particulars | B1: 2020-21 | C1: 2021-22 | D1: 2022-23 | E1: 2023-24 | F1: 2024-25
A2: Revenue | B2: 622425 | C2: 795289 | D2: 909348 | E2: 897943 | F2: 890916
A3: Profit before Depreciation, Amortisation, Interest and Tax | B3: 150709 | C3: 171197 | D3: 173008 | E3: 170170 | F3: 180850
A4: Depreciation and Amortisation | B4: 27656 | C4: 30911 | D4: 33402 | E4: 34071 | F4: 29579
A5: Profit before Interest and Tax | B5: 123053 | C5: 140286 | D5: 139606 | E5: 136099 | F5: 151271
A6: Profit before Tax | B6: 139007 | C6: 151275 | D6: 147657 | E6: 147210 | F6: 174957
A7: Tax | B7: 30345 | C7: 28946 | D7: 33992 | E7: 36089 | F7: 42777
A8: Profit after Tax - attributable to equity holders | B8: 107946 | C8: 122191 | D8: 113500 | E8: 110452 | F8: 131354
A9: Earnings Per Share - Basic (₹) | B9: 9.55 | C9: 11.17 | D9: 10.37 | E9: 10.44 | F9: 12.56
A10: Earnings Per Share - Diluted (₹) | B10: 9.53 | C10: 11.14 | D10: 10.34 | E10: 10.41 | F10: 12.52
A11: Share Capital | B11: 10958 | C11: 10964 | D11: 10976 | E11: 10450 | F11: 20944
A12: Net Worth | B12: 554593 | C12: 658673 | D12: 781753 | E12: 751223 | F12: 830447
A13: Gross Cash (A) | B13: 345500 | C13: 345491 | D13: 401112 | E13: 408124 | F13: 533765
... A23: Market Price Per Share (₹) | B23: 207.1 | C23: 296 | D23: 182.6 | E23: 240.1 | F23: 262.3

Sheet Analysis
A1: Year | B1: Revenue | C1: Operating Profit | D1: Net Profit | F1: Year | G1: Operating Profit (EBIT) | H1: Interest Expense | I1: Interest Coverage Ratio
A2: 2020 | B2: 61137.6 | C2: 12342.3 | D2: 9722.3 | F2: 2020 | G2: 12342.3 | H2: 732.8 | I2: =G2/H2 -> 16.842658
A3: 2021 | B3: 61934.9 | C3: 14771.4 | D3: 10796.4 | F3: 2021 | G3: 14771.4 | H3: 508.8 | I3: =G3/H3 -> 29.03184
A4: 2022 | B4: 79312 | C4: 16684.2 | D4: 12229.6 | F4: 2022 | G4: 16684.2 | H4: 532.5 | I4: =G4/H4 -> 31.331831
A5: 2023 | B5: 90487.6 | C5: 16839 | D5: 11350 | F5: 2023 | G5: 16839 | H5: 1007.7 | I5: =G5/H5 -> 16.71033
A6: 2024 | B6: 89760.3 | C6: 16752.5 | D6: 11045.2 | F6: 2024 | G6: 16752.5 | H6: 1255.2 | I6: =G6/H6 -> 13.346479
A7: 2025 | B7: 89088.4 | C7: 18021.2 | D7: 13135.4 | F7: 2025 | G7: 18021.2 | H7: 1477 | I7: =G7/H7 -> 12.201219
H8: Average | I8: =AVERAGE(I2:I7) -> 19.910726
A9: Year | B9: Revenue | C9: Net Profit | D9: Operating Profit | E9: Shareholders’ Equity
A10: 2020 | B10: 61137.6 | C10: 9722.3 | D10: 12342.3 | E10: 55321.7
A11: 2021 | B11: 61934.9 | C11: 10796.4 | D11: 14771.4 | E11: 54901
A12: 2022 | B12: 79312 | C12: 12229.6 | D12: 16684.2 | E12: 65403
A13: 2023 | B13: 90487.6 | C13: 11350 | D13: 16839 | E13: 77667.9
A14: 2024 | B14: 89760.3 | C14: 11045.2 | D14: 16752.5 | E14: 74988.3
A15: 2025 | B15: 89088.4 | C15: 13135.4 | D15: 18021.2 | E15: 82830.9
F16: 732.8 | G16: 508.8 | H16: 532.5 | I16: 1007.7 | J16: 1255.2 | K16: 1477
A17: Year | B17: Net Profit Margin (%) | C17: Operating Margin (%) | D17: ROE (%) | E17: 186.5 | F17: 106.4 | G17: 133.4 | H17: 118.8 | I17: 90.7 | J17: 69.4
A18: 2020 | B18: =(C10/B10) -> 0.15902325 | C18: =(D10/B10) -> 0.2018774 | D18: =(C10/E10) -> 0.17574116 | E18: 55321.7 | F18: 54901 | G18: 65403 | H18: 77667.9 | I18: 74988.3 | J18: 82830.9
A19: 2021 | B19: =(C11/B11) -> 0.17431852 | C19: =(D11/B11) -> 0.23849881 | D19: =(C11/E11) -> 0.19665216
A20: 2022 | B20: =(C12/B12) -> 0.15419609 | C20: =(D12/B12) -> 0.21036161 | D20: =(C12/E12) -> 0.18698836
A21: 2023 | B21: =(C13/B13) -> 0.12543155 | C21: =(D13/B13) -> 0.1860918 | D21: =(C13/E13) -> 0.14613502
A22: 2024 | B22: =(C14/B14) -> 0.12305217 | C22: =(D14/B14) -> 0.18663596 | D22: =(C14/E14) -> 0.14729231
A23: 2025 | B23: =(C15/B15) -> 0.14744232 | C23: =(D15/B15) -> 0.20228447 | D23: =(C15/E15) -> 0.15858092
A25: YEAR | B25: CURRENT ASSETS (Cr.) | C25: CURRENT LIABILITIES (Cr.) | D25: CURRENT RATIO | F25: Inventory
A26: 2020 | B26: 25083.8 | C26: 15953.9 | D26: =B26/C26 -> 1.5722676 | F26: 186.5
A27: 2021 | B27: 26515.5 | C27: 17213.4 | D27: =B27/C27 -> 1.5403988 | F27: 106.4
A28: 2022 | B28: 22038.9 | C28: 24279.7 | D28: =B28/C28 -> 0.90770891 | F28: 133.4
A29: 2023 | B29: 21941.8 | C29: 21789.2 | D29: =B29/C29 -> 1.0070035 | F29: 118.8
A30: 2024 | B30: 21333.7 | C30: 23611 | D30: =B30/C30 -> 0.90354919 | F30: 90.7
A31: 2025 | B31: 24041.3 | C31: 26361.5 | D31: =B31/C31 -> 0.91198528 | F31: 69.4
C32: Average | D32: =AVERAGE(D26:D31) -> 1.1404855
A34: Year | B34: Quick Assets (Cr.) | C34: Current Liabilities (Cr.) | D34: Quick Ratio
A35: 2020 | B35: =B26-F26 -> 24897.3 | C35: 15953.9 | D35: =B35/C35 -> 1.5605777
A36: 2021 | B36: =B27-F27 -> 26409.1 | C36: 17213.4 | D36: =B36/C36 -> 1.5342175
A37: 2022 | B37: =B28-F28 -> 21905.5 | C37: 24279.7 | D37: =B37/C37 -> 0.90221461
A38: 2023 | B38: =B29-F29 -> 21823 | C38: 21789.2 | D38: =B38/C38 -> 1.0015512
A39: 2024 | B39: =B30-F30 -> 21243 | C39: 23611 | D39: =B39/C39 -> 0.89970776
A40: 2025 | B40: =B31-F31 -> 23971.9 | C40: 26361.5 | D40: =B40/C40 -> 0.90935265
C41: Average | D41: =AVERAGE(D35:D40) -> 1.1346036
A43: Year | B43: Total Debt (Cr.) | C43: Shareholders’ Equity (Cr.) | D43: Debt–Equity Ratio
...
